scripts/instr_concurr_test_large.in
8
0-7 o

0 B 0 AAPL 888 10
1 B 1 AAPL 888 10
0 B 2 AAPL 888 10
1 B 3 AAPL 888 10
0 B 4 AAPL 888 10
1 B 5 AAPL 888 10
0 B 6 AAPL 888 10
1 B 7 AAPL 888 10
0 B 8 AAPL 888 10
1 B 9 AAPL 888 10
0 B 10 AAPL 888 10
1 B 11 AAPL 888 10
0 B 12 AAPL 888 10
1 B 13 AAPL 888 10
0 B 14 AAPL 888 10
1 B 15 AAPL 888 10
0 B 16 AAPL 888 10
1 B 17 AAPL 888 10
0 B 18 AAPL 888 10
1 B 19 AAPL 888 10
0 B 20 AAPL 888 10
1 B 21 AAPL 888 10
0 B 22 AAPL 888 10
1 B 23 AAPL 888 10
0 B 24 AAPL 888 10
1 B 25 AAPL 888 10
0 B 26 AAPL 888 10
1 B 27 AAPL 888 10
0 B 28 AAPL 888 10
1 B 29 AAPL 888 10
0 B 30 AAPL 888 10
1 B 31 AAPL 888 10
0 B 32 AAPL 888 10
1 B 33 AAPL 888 10
0 B 34 AAPL 888 10
1 B 35 AAPL 888 10
0 B 36 AAPL 888 10
1 B 37 AAPL 888 10
0 B 38 AAPL 888 10
1 B 39 AAPL 888 10
0 B 40 AAPL 888 10
1 B 41 AAPL 888 10
0 B 42 AAPL 888 10
1 B 43 AAPL 888 10
0 B 44 AAPL 888 10
1 B 45 AAPL 888 10
0 B 46 AAPL 888 10
1 B 47 AAPL 888 10
0 B 48 AAPL 888 10
1 B 49 AAPL 888 10
0 B 50 AAPL 888 10
1 B 51 AAPL 888 10
0 B 52 AAPL 888 10
1 B 53 AAPL 888 10
0 B 54 AAPL 888 10
1 B 55 AAPL 888 10
0 B 56 AAPL 888 10
1 B 57 AAPL 888 10
0 B 58 AAPL 888 10
1 B 59 AAPL 888 10
0 B 60 AAPL 888 10
1 B 61 AAPL 888 10
0 B 62 AAPL 888 10
1 B 63 AAPL 888 10
0 B 64 AAPL 888 10
1 B 65 AAPL 888 10
0 B 66 AAPL 888 10
1 B 67 AAPL 888 10
0 B 68 AAPL 888 10
1 B 69 AAPL 888 10
0 B 70 AAPL 888 10
1 B 71 AAPL 888 10
0 B 72 AAPL 888 10
1 B 73 AAPL 888 10
0 B 74 AAPL 888 10
1 B 75 AAPL 888 10
0 B 76 AAPL 888 10
1 B 77 AAPL 888 10
0 B 78 AAPL 888 10
1 B 79 AAPL 888 10
0 B 80 AAPL 888 10
1 B 81 AAPL 888 10
0 B 82 AAPL 888 10
1 B 83 AAPL 888 10
0 B 84 AAPL 888 10
1 B 85 AAPL 888 10
0 B 86 AAPL 888 10
1 B 87 AAPL 888 10
0 B 88 AAPL 888 10
1 B 89 AAPL 888 10
0 B 90 AAPL 888 10
1 B 91 AAPL 888 10
0 B 92 AAPL 888 10
1 B 93 AAPL 888 10
0 B 94 AAPL 888 10
1 B 95 AAPL 888 10
0 B 96 AAPL 888 10
1 B 97 AAPL 888 10
0 B 98 AAPL 888 10
1 B 99 AAPL 888 10
0 B 100 AAPL 888 10
1 B 101 AAPL 888 10
0 B 102 AAPL 888 10
1 B 103 AAPL 888 10
0 B 104 AAPL 888 10
1 B 105 AAPL 888 10
0 B 106 AAPL 888 10
1 B 107 AAPL 888 10
0 B 108 AAPL 888 10
1 B 109 AAPL 888 10
0 B 110 AAPL 888 10
1 B 111 AAPL 888 10
0 B 112 AAPL 888 10
1 B 113 AAPL 888 10
0 B 114 AAPL 888 10
1 B 115 AAPL 888 10
0 B 116 AAPL 888 10
1 B 117 AAPL 888 10
0 B 118 AAPL 888 10
1 B 119 AAPL 888 10
0 B 120 AAPL 888 10
1 B 121 AAPL 888 10
0 B 122 AAPL 888 10
1 B 123 AAPL 888 10
0 B 124 AAPL 888 10
1 B 125 AAPL 888 10
0 B 126 AAPL 888 10
1 B 127 AAPL 888 10
0 B 128 AAPL 888 10
1 B 129 AAPL 888 10
0 B 130 AAPL 888 10
1 B 131 AAPL 888 10
0 B 132 AAPL 888 10
1 B 133 AAPL 888 10
0 B 134 AAPL 888 10
1 B 135 AAPL 888 10
0 B 136 AAPL 888 10
1 B 137 AAPL 888 10
0 B 138 AAPL 888 10
1 B 139 AAPL 888 10
0 B 140 AAPL 888 10
1 B 141 AAPL 888 10
0 B 142 AAPL 888 10
1 B 143 AAPL 888 10
0 B 144 AAPL 888 10
1 B 145 AAPL 888 10
0 B 146 AAPL 888 10
1 B 147 AAPL 888 10
0 B 148 AAPL 888 10
1 B 149 AAPL 888 10
0 B 150 AAPL 888 10
1 B 151 AAPL 888 10
0 B 152 AAPL 888 10
1 B 153 AAPL 888 10
0 B 154 AAPL 888 10
1 B 155 AAPL 888 10
0 B 156 AAPL 888 10
1 B 157 AAPL 888 10
0 B 158 AAPL 888 10
1 B 159 AAPL 888 10
0 B 160 AAPL 888 10
1 B 161 AAPL 888 10
0 B 162 AAPL 888 10
1 B 163 AAPL 888 10
0 B 164 AAPL 888 10
1 B 165 AAPL 888 10
0 B 166 AAPL 888 10
1 B 167 AAPL 888 10
0 B 168 AAPL 888 10
1 B 169 AAPL 888 10
0 B 170 AAPL 888 10
1 B 171 AAPL 888 10
0 B 172 AAPL 888 10
1 B 173 AAPL 888 10
0 B 174 AAPL 888 10
1 B 175 AAPL 888 10
0 B 176 AAPL 888 10
1 B 177 AAPL 888 10
0 B 178 AAPL 888 10
1 B 179 AAPL 888 10
0 B 180 AAPL 888 10
1 B 181 AAPL 888 10
0 B 182 AAPL 888 10
1 B 183 AAPL 888 10
0 B 184 AAPL 888 10
1 B 185 AAPL 888 10
0 B 186 AAPL 888 10
1 B 187 AAPL 888 10
0 B 188 AAPL 888 10
1 B 189 AAPL 888 10
0 B 190 AAPL 888 10
1 B 191 AAPL 888 10
0 B 192 AAPL 888 10
1 B 193 AAPL 888 10
0 B 194 AAPL 888 10
1 B 195 AAPL 888 10
0 B 196 AAPL 888 10
1 B 197 AAPL 888 10
0 B 198 AAPL 888 10
1 B 199 AAPL 888 10
0 B 200 AAPL 888 10
1 B 201 AAPL 888 10
0 B 202 AAPL 888 10
1 B 203 AAPL 888 10
0 B 204 AAPL 888 10
1 B 205 AAPL 888 10
0 B 206 AAPL 888 10
1 B 207 AAPL 888 10
0 B 208 AAPL 888 10
1 B 209 AAPL 888 10
0 B 210 AAPL 888 10
1 B 211 AAPL 888 10
0 B 212 AAPL 888 10
1 B 213 AAPL 888 10
0 B 214 AAPL 888 10
1 B 215 AAPL 888 10
0 B 216 AAPL 888 10
1 B 217 AAPL 888 10
0 B 218 AAPL 888 10
1 B 219 AAPL 888 10
0 B 220 AAPL 888 10
1 B 221 AAPL 888 10
0 B 222 AAPL 888 10
1 B 223 AAPL 888 10
0 B 224 AAPL 888 10
1 B 225 AAPL 888 10
0 B 226 AAPL 888 10
1 B 227 AAPL 888 10
0 B 228 AAPL 888 10
1 B 229 AAPL 888 10
0 B 230 AAPL 888 10
1 B 231 AAPL 888 10
0 B 232 AAPL 888 10
1 B 233 AAPL 888 10
0 B 234 AAPL 888 10
1 B 235 AAPL 888 10
0 B 236 AAPL 888 10
1 B 237 AAPL 888 10
0 B 238 AAPL 888 10
1 B 239 AAPL 888 10
0 B 240 AAPL 888 10
1 B 241 AAPL 888 10
0 B 242 AAPL 888 10
1 B 243 AAPL 888 10
0 B 244 AAPL 888 10
1 B 245 AAPL 888 10
0 B 246 AAPL 888 10
1 B 247 AAPL 888 10
0 B 248 AAPL 888 10
1 B 249 AAPL 888 10
0 B 250 AAPL 888 10
1 B 251 AAPL 888 10
0 B 252 AAPL 888 10
1 B 253 AAPL 888 10
0 B 254 AAPL 888 10
1 B 255 AAPL 888 10
0 B 256 AAPL 888 10
1 B 257 AAPL 888 10
0 B 258 AAPL 888 10
1 B 259 AAPL 888 10
0 B 260 AAPL 888 10
1 B 261 AAPL 888 10
0 B 262 AAPL 888 10
1 B 263 AAPL 888 10
0 B 264 AAPL 888 10
1 B 265 AAPL 888 10
0 B 266 AAPL 888 10
1 B 267 AAPL 888 10
0 B 268 AAPL 888 10
1 B 269 AAPL 888 10
0 B 270 AAPL 888 10
1 B 271 AAPL 888 10
0 B 272 AAPL 888 10
1 B 273 AAPL 888 10
0 B 274 AAPL 888 10
1 B 275 AAPL 888 10
0 B 276 AAPL 888 10
1 B 277 AAPL 888 10
0 B 278 AAPL 888 10
1 B 279 AAPL 888 10
0 B 280 AAPL 888 10
1 B 281 AAPL 888 10
0 B 282 AAPL 888 10
1 B 283 AAPL 888 10
0 B 284 AAPL 888 10
1 B 285 AAPL 888 10
0 B 286 AAPL 888 10
1 B 287 AAPL 888 10
0 B 288 AAPL 888 10
1 B 289 AAPL 888 10
0 B 290 AAPL 888 10
1 B 291 AAPL 888 10
0 B 292 AAPL 888 10
1 B 293 AAPL 888 10
0 B 294 AAPL 888 10
1 B 295 AAPL 888 10
0 B 296 AAPL 888 10
1 B 297 AAPL 888 10
0 B 298 AAPL 888 10
1 B 299 AAPL 888 10
0 B 300 AAPL 888 10
1 B 301 AAPL 888 10
0 B 302 AAPL 888 10
1 B 303 AAPL 888 10
0 B 304 AAPL 888 10
1 B 305 AAPL 888 10
0 B 306 AAPL 888 10
1 B 307 AAPL 888 10
0 B 308 AAPL 888 10
1 B 309 AAPL 888 10
0 B 310 AAPL 888 10
1 B 311 AAPL 888 10
0 B 312 AAPL 888 10
1 B 313 AAPL 888 10
0 B 314 AAPL 888 10
1 B 315 AAPL 888 10
0 B 316 AAPL 888 10
1 B 317 AAPL 888 10
0 B 318 AAPL 888 10
1 B 319 AAPL 888 10
0 B 320 AAPL 888 10
1 B 321 AAPL 888 10
0 B 322 AAPL 888 10
1 B 323 AAPL 888 10
0 B 324 AAPL 888 10
1 B 325 AAPL 888 10
0 B 326 AAPL 888 10
1 B 327 AAPL 888 10
0 B 328 AAPL 888 10
1 B 329 AAPL 888 10
0 B 330 AAPL 888 10
1 B 331 AAPL 888 10
0 B 332 AAPL 888 10
1 B 333 AAPL 888 10
0 B 334 AAPL 888 10
1 B 335 AAPL 888 10
0 B 336 AAPL 888 10
1 B 337 AAPL 888 10
0 B 338 AAPL 888 10
1 B 339 AAPL 888 10
0 B 340 AAPL 888 10
1 B 341 AAPL 888 10
0 B 342 AAPL 888 10
1 B 343 AAPL 888 10
0 B 344 AAPL 888 10
1 B 345 AAPL 888 10
0 B 346 AAPL 888 10
1 B 347 AAPL 888 10
0 B 348 AAPL 888 10
1 B 349 AAPL 888 10
0 B 350 AAPL 888 10
1 B 351 AAPL 888 10
0 B 352 AAPL 888 10
1 B 353 AAPL 888 10
0 B 354 AAPL 888 10
1 B 355 AAPL 888 10
0 B 356 AAPL 888 10
1 B 357 AAPL 888 10
0 B 358 AAPL 888 10
1 B 359 AAPL 888 10
0 B 360 AAPL 888 10
1 B 361 AAPL 888 10
0 B 362 AAPL 888 10
1 B 363 AAPL 888 10
0 B 364 AAPL 888 10
1 B 365 AAPL 888 10
0 B 366 AAPL 888 10
1 B 367 AAPL 888 10
0 B 368 AAPL 888 10
1 B 369 AAPL 888 10
0 B 370 AAPL 888 10
1 B 371 AAPL 888 10
0 B 372 AAPL 888 10
1 B 373 AAPL 888 10
0 B 374 AAPL 888 10
1 B 375 AAPL 888 10
0 B 376 AAPL 888 10
1 B 377 AAPL 888 10
0 B 378 AAPL 888 10
1 B 379 AAPL 888 10
0 B 380 AAPL 888 10
1 B 381 AAPL 888 10
0 B 382 AAPL 888 10
1 B 383 AAPL 888 10
0 B 384 AAPL 888 10
1 B 385 AAPL 888 10
0 B 386 AAPL 888 10
1 B 387 AAPL 888 10
0 B 388 AAPL 888 10
1 B 389 AAPL 888 10
0 B 390 AAPL 888 10
1 B 391 AAPL 888 10
0 B 392 AAPL 888 10
1 B 393 AAPL 888 10
0 B 394 AAPL 888 10
1 B 395 AAPL 888 10
0 B 396 AAPL 888 10
1 B 397 AAPL 888 10
0 B 398 AAPL 888 10
1 B 399 AAPL 888 10
0 B 400 AAPL 888 10
1 B 401 AAPL 888 10
0 B 402 AAPL 888 10
1 B 403 AAPL 888 10
0 B 404 AAPL 888 10
1 B 405 AAPL 888 10
