scripts/instr_concurr_test_large_randomised.in
8
0-7 o

2 S 808 AAPL 888 10
6 B 1990 GOOG 888 10
7 B 1979 GOOG 888 10
6 B 1882 GOOG 888 10
4 S 1096 GOOG 888 10
5 S 1371 GOOG 888 10
3 S 897 AAPL 888 10
5 S 1013 GOOG 888 10
3 S 627 AAPL 888 10

0 B 220 AAPL 888 10
7 B 1907 GOOG 888 10
6 B 1604 GOOG 888 10
4 S 1108 GOOG 888 10
5 S 1235 GOOG 888 10
2 S 574 AAPL 888 10
3 S 951 AAPL 888 10
3 S 955 AAPL 888 10
7 B 1791 GOOG 888 10
6 B 1750 GOOG 888 10
3 S 917 AAPL 888 10
0 B 246 AAPL 888 10
3 S 843 AAPL 888 10
1 B 109 AAPL 888 10
1 B 187 AAPL 888 10
4 S 1476 GOOG 888 10
2 S 500 AAPL 888 10
0 B 252 AAPL 888 10
0 B 88 AAPL 888 10
6 B 1968 GOOG 888 10
6 B 1694 GOOG 888 10
0 B 172 AAPL 888 10
2 S 710 AAPL 888 10
2 S 608 AAPL 888 10
7 B 1809 GOOG 888 10
7 B 1743 GOOG 888 10
0 B 384 AAPL 888 10
5 S 1405 GOOG 888 10
1 B 171 AAPL 888 10
4 S 1270 GOOG 888 10
2 S 812 AAPL 888 10
3 S 849 AAPL 888 10
0 B 164 AAPL 888 10
0 B 342 AAPL 888 10
5 S 1189 GOOG 888 10
3 S 919 AAPL 888 10
2 S 634 AAPL 888 10
4 S 1498 GOOG 888 10
1 B 321 AAPL 888 10
1 B 31 AAPL 888 10
1 B 269 AAPL 888 10
5 S 1117 GOOG 888 10
4 S 1292 GOOG 888 10
1 B 439 AAPL 888 10
0 B 114 AAPL 888 10
4 S 1496 GOOG 888 10
1 B 229 AAPL 888 10
1 B 161 AAPL 888 10
6 B 1626 GOOG 888 10
4 S 1160 GOOG 888 10
0 B 42 AAPL 888 10
2 S 620 AAPL 888 10
0 B 360 AAPL 888 10
2 S 566 AAPL 888 10
7 B 1705 GOOG 888 10
3 S 967 AAPL 888 10
1 B 287 AAPL 888 10
1 B 285 AAPL 888 10
4 S 1442 GOOG 888 10
5 S 1483 GOOG 888 10
6 B 1760 GOOG 888 10
0 B 426 AAPL 888 10
7 B 1657 GOOG 888 10
1 B 51 AAPL 888 10
1 B 295 AAPL 888 10
2 S 794 AAPL 888 10
3 S 509 AAPL 888 10
0 B 212 AAPL 888 10
0 B 28 AAPL 888 10
3 S 607 AAPL 888 10
4 S 1480 GOOG 888 10
0 B 420 AAPL 888 10
5 S 1181 GOOG 888 10
5 S 1461 GOOG 888 10
6 B 1696 GOOG 888 10
6 B 1656 GOOG 888 10
1 B 3 AAPL 888 10
4 S 1120 GOOG 888 10
5 S 1497 GOOG 888 10
7 B 1691 GOOG 888 10
3 S 585 AAPL 888 10
6 B 1992 GOOG 888 10
4 S 1038 GOOG 888 10
7 B 1813 GOOG 888 10
7 B 1603 GOOG 888 10
6 B 1862 GOOG 888 10
0 B 216 AAPL 888 10
2 S 788 AAPL 888 10
4 S 1346 GOOG 888 10
3 S 633 AAPL 888 10
5 S 1237 GOOG 888 10
3 S 689 AAPL 888 10
0 B 468 AAPL 888 10
2 S 616 AAPL 888 10
5 S 1425 GOOG 888 10
6 B 1838 GOOG 888 10
5 S 1123 GOOG 888 10
3 S 697 AAPL 888 10
7 B 1905 GOOG 888 10
6 B 1628 GOOG 888 10
7 B 1509 GOOG 888 10
2 S 626 AAPL 888 10
4 S 1280 GOOG 888 10
1 B 209 AAPL 888 10
5 S 1369 GOOG 888 10
5 S 1347 GOOG 888 10
0 B 432 AAPL 888 10
5 S 1207 GOOG 888 10
6 B 1584 GOOG 888 10
5 S 1009 GOOG 888 10
6 B 1906 GOOG 888 10
3 S 975 AAPL 888 10
1 B 271 AAPL 888 10
6 B 1566 GOOG 888 10
3 S 857 AAPL 888 10
6 B 1816 GOOG 888 10
4 S 1366 GOOG 888 10
6 B 1770 GOOG 888 10
5 S 1229 GOOG 888 10
3 S 647 AAPL 888 10
7 B 1807 GOOG 888 10
0 B 140 AAPL 888 10
1 B 413 AAPL 888 10
3 S 559 AAPL 888 10
3 S 635 AAPL 888 10
7 B 1883 GOOG 888 10
3 S 637 AAPL 888 10
0 B 416 AAPL 888 10
1 B 205 AAPL 888 10
5 S 1333 GOOG 888 10
0 B 54 AAPL 888 10
6 B 1578 GOOG 888 10
4 S 1392 GOOG 888 10
3 S 871 AAPL 888 10
5 S 1359 GOOG 888 10
7 B 1605 GOOG 888 10
3 S 571 AAPL 888 10
7 B 1615 GOOG 888 10
2 S 894 AAPL 888 10
7 B 1825 GOOG 888 10
1 B 217 AAPL 888 10
7 B 1939 GOOG 888 10
6 B 1544 GOOG 888 10
1 B 319 AAPL 888 10
4 S 1214 GOOG 888 10
3 S 903 AAPL 888 10
5 S 1135 GOOG 888 10
7 B 1675 GOOG 888 10
6 B 1786 GOOG 888 10
7 B 1753 GOOG 888 10
2 S 958 AAPL 888 10
6 B 1948 GOOG 888 10
7 B 1767 GOOG 888 10
0 B 258 AAPL 888 10
7 B 1553 GOOG 888 10
5 S 1155 GOOG 888 10
6 B 1958 GOOG 888 10
1 B 53 AAPL 888 10
2 S 980 AAPL 888 10
6 B 1600 GOOG 888 10
4 S 1316 GOOG 888 10
0 B 386 AAPL 888 10
3 S 673 AAPL 888 10
4 S 1400 GOOG 888 10
6 B 1754 GOOG 888 10
0 B 396 AAPL 888 10
4 S 1380 GOOG 888 10
1 B 257 AAPL 888 10
3 S 741 AAPL 888 10
5 S 1023 GOOG 888 10
2 S 610 AAPL 888 10
6 B 1964 GOOG 888 10
1 B 289 AAPL 888 10
1 B 249 AAPL 888 10
2 S 956 AAPL 888 10
3 S 921 AAPL 888 10
7 B 1661 GOOG 888 10
4 S 1342 GOOG 888 10
0 B 444 AAPL 888 10
4 S 1340 GOOG 888 10
1 B 153 AAPL 888 10
7 B 1969 GOOG 888 10
4 S 1198 GOOG 888 10
0 B 120 AAPL 888 10
6 B 1938 GOOG 888 10
4 S 1252 GOOG 888 10
7 B 1881 GOOG 888 10
0 B 148 AAPL 888 10
0 B 76 AAPL 888 10
2 S 832 AAPL 888 10
6 B 1812 GOOG 888 10
3 S 877 AAPL 888 10
1 B 409 AAPL 888 10
1 B 97 AAPL 888 10
3 S 811 AAPL 888 10
4 S 1216 GOOG 888 10
2 S 972 AAPL 888 10
6 B 1650 GOOG 888 10
3 S 611 AAPL 888 10
2 S 806 AAPL 888 10
5 S 1185 GOOG 888 10
3 S 593 AAPL 888 10
1 B 387 AAPL 888 10
2 S 598 AAPL 888 10
5 S 1101 GOOG 888 10
3 S 565 AAPL 888 10
0 B 262 AAPL 888 10
5 S 1069 GOOG 888 10
6 B 1642 GOOG 888 10
1 B 261 AAPL 888 10
3 S 763 AAPL 888 10
4 S 1348 GOOG 888 10
3 S 723 AAPL 888 10
6 B 1730 GOOG 888 10
0 B 398 AAPL 888 10
5 S 1463 GOOG 888 10
2 S 990 AAPL 888 10
6 B 1934 GOOG 888 10
4 S 1232 GOOG 888 10
0 B 198 AAPL 888 10
6 B 1960 GOOG 888 10
1 B 357 AAPL 888 10
0 B 404 AAPL 888 10
2 S 798 AAPL 888 10

5 S 1027 GOOG 888 10
6 B 1852 GOOG 888 10
1 B 183 AAPL 888 10
3 S 577 AAPL 888 10
2 S 618 AAPL 888 10
7 B 1777 GOOG 888 10
6 B 1568 GOOG 888 10
5 S 1125 GOOG 888 10
4 S 1066 GOOG 888 10
4 S 1070 GOOG 888 10
1 B 475 AAPL 888 10
2 S 784 AAPL 888 10
2 S 502 AAPL 888 10
6 B 1850 GOOG 888 10
4 S 1112 GOOG 888 10
3 S 901 AAPL 888 10
2 S 670 AAPL 888 10
7 B 1957 GOOG 888 10
0 B 336 AAPL 888 10
4 S 1422 GOOG 888 10
5 S 1145 GOOG 888 10
6 B 1522 GOOG 888 10
3 S 981 AAPL 888 10
0 B 78 AAPL 888 10
4 S 1180 GOOG 888 10
5 S 1383 GOOG 888 10
1 B 429 AAPL 888 10
1 B 403 AAPL 888 10
5 S 1445 GOOG 888 10
5 S 1091 GOOG 888 10
6 B 1988 GOOG 888 10
5 S 1191 GOOG 888 10
4 S 1414 GOOG 888 10
2 S 874 AAPL 888 10
5 S 1167 GOOG 888 10
4 S 1176 GOOG 888 10
0 B 368 AAPL 888 10
1 B 139 AAPL 888 10
3 S 845 AAPL 888 10
2 S 918 AAPL 888 10
0 B 242 AAPL 888 10
2 S 622 AAPL 888 10
6 B 1510 GOOG 888 10
1 B 495 AAPL 888 10
1 B 347 AAPL 888 10
2 S 724 AAPL 888 10
4 S 1194 GOOG 888 10
7 B 1711 GOOG 888 10
7 B 1649 GOOG 888 10
5 S 1431 GOOG 888 10
2 S 558 AAPL 888 10
1 B 169 AAPL 888 10
3 S 863 AAPL 888 10
4 S 1376 GOOG 888 10
4 S 1058 GOOG 888 10
5 S 1403 GOOG 888 10
6 B 1512 GOOG 888 10
5 S 1215 GOOG 888 10
0 B 146 AAPL 888 10
3 S 929 AAPL 888 10
7 B 1949 GOOG 888 10
4 S 1152 GOOG 888 10
4 S 1174 GOOG 888 10
2 S 728 AAPL 888 10
0 B 228 AAPL 888 10
5 S 1487 GOOG 888 10
2 S 536 AAPL 888 10
1 B 323 AAPL 888 10
3 S 759 AAPL 888 10
4 S 1208 GOOG 888 10
4 S 1202 GOOG 888 10
4 S 1256 GOOG 888 10
1 B 333 AAPL 888 10
0 B 130 AAPL 888 10
6 B 1652 GOOG 888 10
2 S 642 AAPL 888 10
3 S 521 AAPL 888 10
2 S 844 AAPL 888 10
4 S 1384 GOOG 888 10
3 S 519 AAPL 888 10
5 S 1437 GOOG 888 10
5 S 1269 GOOG 888 10
1 B 493 AAPL 888 10
1 B 277 AAPL 888 10
5 S 1367 GOOG 888 10
2 S 936 AAPL 888 10
4 S 1082 GOOG 888 10
4 S 1170 GOOG 888 10
7 B 1559 GOOG 888 10
3 S 733 AAPL 888 10
5 S 1059 GOOG 888 10
3 S 989 AAPL 888 10
2 S 828 AAPL 888 10
4 S 1188 GOOG 888 10
2 S 876 AAPL 888 10
0 B 372 AAPL 888 10
3 S 603 AAPL 888 10
1 B 337 AAPL 888 10
2 S 524 AAPL 888 10
3 S 959 AAPL 888 10
5 S 1323 GOOG 888 10
4 S 1186 GOOG 888 10
4 S 1262 GOOG 888 10
6 B 1714 GOOG 888 10
7 B 1683 GOOG 888 10
6 B 1932 GOOG 888 10
7 B 1875 GOOG 888 10
2 S 928 AAPL 888 10
6 B 1978 GOOG 888 10
3 S 503 AAPL 888 10
2 S 772 AAPL 888 10
7 B 1765 GOOG 888 10
0 B 282 AAPL 888 10
2 S 740 AAPL 888 10
3 S 761 AAPL 888 10
0 B 238 AAPL 888 10
2 S 756 AAPL 888 10
5 S 1265 GOOG 888 10
5 S 1375 GOOG 888 10
4 S 1142 GOOG 888 10
4 S 1334 GOOG 888 10
7 B 1849 GOOG 888 10
7 B 1569 GOOG 888 10
6 B 1916 GOOG 888 10
6 B 1520 GOOG 888 10
4 S 1008 GOOG 888 10
7 B 1627 GOOG 888 10
2 S 680 AAPL 888 10
4 S 1302 GOOG 888 10
2 S 602 AAPL 888 10
2 S 648 AAPL 888 10
0 B 296 AAPL 888 10
5 S 1251 GOOG 888 10
6 B 1912 GOOG 888 10
3 S 987 AAPL 888 10
3 S 665 AAPL 888 10
3 S 595 AAPL 888 10
1 B 159 AAPL 888 10
5 S 1397 GOOG 888 10
7 B 1645 GOOG 888 10
6 B 1524 GOOG 888 10
3 S 821 AAPL 888 10
6 B 1528 GOOG 888 10
5 S 1479 GOOG 888 10
6 B 1572 GOOG 888 10
2 S 934 AAPL 888 10
1 B 83 AAPL 888 10
4 S 1412 GOOG 888 10
6 B 1864 GOOG 888 10
3 S 785 AAPL 888 10
7 B 1601 GOOG 888 10
4 S 1310 GOOG 888 10
2 S 764 AAPL 888 10
4 S 1428 GOOG 888 10
0 B 316 AAPL 888 10
7 B 1581 GOOG 888 10
5 S 1213 GOOG 888 10
2 S 744 AAPL 888 10
